Workbook
Name RefUnitTest: 'Input Data'!$B$5
Name RefIntegrationTest: 'Input Data'!$B$6
Name RefCodeReview: 'Input Data'!$B$7
Name RefManualQA: 'Input Data'!$B$8
Name RefAQA: 'Input Data'!$B$9
Name RefBugFix: 'Input Data'!$B$10
Name RefDocumentation: 'Input Data'!$B$11
Name RefCommunication: 'Input Data'!$B$12
Name RefRate: 'Input Data'!$B$13
Name EnumRoles: 'Input Data'!$F$17:$F$29
Name EnumSeniorities: 'Input Data'!$H$17:$H$23
Name EnumPhase: 'Input Data'!$J$17:$J$22
Name EnumLocations: 'Input Data'!$L$17:$L$21
Name EnumYesNo: 'Input Data'!$N$17:$N$18
Name EnumInclude: 'Input Data'!$P$17:$P$18

Sheet Usage Manual
A1: WBS and Estimates v1.5 — Usage Manual
A2: A presale/delivery estimation pack. PERT 3-point estimation per discipline, reconciled into one resource and cost model with profitability and a maintenance run-rate.
A4: Document conventions
B5: Color coding | C5: GRAY = hardcoded input (do not edit). BLUE = computed (do not edit). GREEN = editable (estimator inputs go here). YELLOW = epic / section / guidance row. ORANGE = validation warning (P/O ratio > 5 or O>ML>P).
B6: Per-tab guidance | C6: Every tab has a yellow guidance block at the top with Purpose / How to use / Inputs / Outputs / Linked tabs. Read it before editing.
B7: Named ranges | C7: Coefficients and enums are named ranges (RefBugFix, RefRate, EnumRoles, ...). Edit them on the Input Data tab; references update everywhere.
A8: Methodology
B9: PERT formulas | C9: Expected = (O + 4*ML + P)/6. StdDev = (P - O)/6. Variance = StdDev^2. Project Buffer on the Buffers tab = Subtotal + Z * sqrt(Sum(Variance)). Z = 0 (50%) / 1 (84%) / 2 (97%) confidence.
B10: Two layers of risk | C10: (1) Per-line Contingency on every Est tab (Apply = Yes => add ML * default_contingency to Expected). Use this for SPECIFIC uncertain items (KYC, blockchain, vendor APIs). (2) Project-wide PERT Z-score buffer on the Buffers tab. Use this for OVERALL confidence interval on the SOW.
B11: Augmentation coefficients | C11: On the WBS tab, Augmented = Base * (1 + UnitTest + IntegrationTest + CodeReview). Bugfix / Documentation / Communication are added on the Buffers tab as % of Buffered total.
B12: QA derivation | C12: Manual QA = (BE + FE) * RefManualQA. AQA = (BE + FE) * RefAQA. v1.5 fixes the v1.4 bug where QA variance was not propagated — Z-score buffer now applies to QA too. Alternative: use the QA Estimation tab for a per-stream QA WBS and override these coefficients.
B13: Cost layering | C13: (a) FTE cost from Headcount and Cost (rate looked up by Role x Seniority x Location on Rates tab; falls back to RefRate if no match). (b) Fixed Costs tab adds lump sums (pen test, audit, ...). (c) Maintenance tab models post go-live monthly run rate. (d) Internal Cost & Profitability gives margin.
A14: Workflow — order of operations
B15: Step 1 — Set context | C15: Fill Check-list (estimator names + reviews). Fill Solution Context & Sizing (#products, channels, integrations, durations, risks). Without these the number is unfalsifiable.
B16: Step 2 — Build WBS | C16: On WBS and Estimates, replace seed rows with your epics and user stories. Use stable IDs (E-1, US-1.3). Per row: enter O/ML/P for BE and FE, set Include / Phase / Milestone, write Assumptions / Description / Out of Scope / Jira link. Validation will flag P/O > 5 or O>ML>P in orange.
B17: Step 3 — Apply per-line contingency | C17: For HIGH-UNCERTAINTY rows set Apply Contingency = Yes. The default contingency is per-discipline (BA 20%, Arch 30%, QA 15%, DevOps 30%, PM 20%, UIUX 20%); on WBS the contingency is entered manually per row.
B18: Step 4 — Fill discipline tabs | C18: BA / Arch / QA / DevOps / PM / UIUX. Same column shape on each tab. Mark Include / Phase per item. Items left at zero hours are still in the catalogue but excluded from totals.
B19: Step 5 — Set Z-score | C19: On Buffers & Non-Dev Activities choose Z (0..2). Higher = more buffer = more conservative SOW. Default 1.0 (84% CI).
B20: Step 6 — Maintain Rates | C20: Edit Rates tab: rows are (Role x Seniority x Location => $/h). Headcount and Cost looks up rate via INDEX/MATCH. If no row matches the resource's (Role, Seniority, Location), the formula falls back to RefRate.
B21: Step 7 — Allocate resources | C21: On Headcount and Cost, add a row per resource with Role / Seniority / Location / Headcount / Allocation / Start Week / End Week. The right-hand 'Estimated vs Allocated' panel computes Delta Hours per role; minimize the absolute value.
B22: Step 8 — Add fixed costs | C22: On Fixed Costs add 3rd-party items (pen test, audit, perf test, KYC vendor licenses, cloud cost). Set Include = Included / Not included / Post-MVP.
B23: Step 9 — Verify margin | C23: On Internal Cost & Profitability check 'Project Profitability (build)' is at or above the desired threshold. If not, revisit Rates / seniority mix / scope.
B24: Step 10 — Plan maintenance | C24: Fill the Maintenance tab. Annual Run-rate is exposed; quote it separately in the SOW.
B25: Step 11 — Use reports | C25: Epic Weight ranks epics by cost (sponsor view). Monthly Cost Roll-out shows cash-flow profile. WBS Comparison stores snapshots so scope creep between versions is visible.
B26: Step 12 — Peer review & sign-off | C26: Update Check-list reviews to 'Yes' once Architecture / Design / BA / QA / DevOps / Estimation peer reviews complete. DM/PM final sign-off last.
A27: Tab index
B28: Check-list | C28: WHO estimated and WHAT was reviewed. Use it as the audit trail.
B29: Solution Context & Sizing | C29: WHY the number is what it is. Records the assumptions the estimate is conditioned on.
B30: WBS and Estimates | C30: Hierarchical Epic > User Story with BE/FE PERT estimates and per-row metadata.
B31: BA / Arch / QA / DevOps / PM / UIUX Estimation | C31: Per-discipline WBS. Replace the catalogue with reality and toggle Include/Phase per item.
B32: Buffers & Non-Dev Activities | C32: Applies PERT Z-score, Bugfix/Doc/Communication coefficients, derives MQA/AQA, adds discipline roll-ups.
B33: Rates | C33: Role x Seniority x Location rate card.
B34: Headcount and Cost | C34: Resource allocation grid with rate lookup; reconciles allocated vs estimated.
B35: Internal Cost & Profitability | C35: Salary + tax + overhead per resource; project profitability.
B36: Monthly Cost Roll-out | C36: Spreads allocated cost across months for cash-flow.
B37: Fixed Costs | C37: Lump-sum / 3rd-party costs included or excluded from the proposal.
B38: Maintenance | C38: Post go-live monthly + annual run-rate.
B39: Epic Weight | C39: Cost-by-epic ranking for sponsor conversations.
... B41: Input Data | C41: Global coefficients, blended-rate fallback, enums for dropdowns.
A42: Field glossary
...

Sheet Check-list
A1: Check-list — Estimator team & reviews
A2: Purpose: | B2: Audit trail for the estimate. Records WHO contributed each role's number and WHICH reviews have been completed. Without it, the workbook is anonymous and undefendable.
A3: How to use: | B3: Fill the names per role. As each review (Architecture / Design / BA / QA / DevOps / Peer / DM-PM sign-off) completes, set State = Yes and add Date + Reviewer. Mandatory calculations at the bottom point to where each KPI lives so a reviewer can verify them.
A4: Inputs: | B4: Names (manual). Review states / dates / reviewers (manual). KPI values can be linked from other tabs.
A5: Outputs: | B5: A single-page record that proves who estimated and who signed off.
A6: Linked tabs: | B6: Mandatory calculations point to: Internal Cost & Profitability, Headcount and Cost, Maintenance.
B8: Role / responsibility | C8: Last name, First name
B9: DM responsible for estimation
B10: PM responsible for estimation (if any)
A12: Estimation Team
B13: Role | C13: Last name, First name
B14: Solution Architect
B15: Software Architect
B16: Data Architect
B17: Lead BA / BA
B18: Lead QA / QA
B19: DevOps
B20: Designer (UI/UX)
B21: Front-end Web Developer
B22: Front-end Mobile Developer
B23: Back-end Developer
B24: Other
A26: Reviews
B27: Review type | C27: State | D27: Date | E27: Reviewer
B28: Architecture Review | C28: Yes
B29: Design Review (if any)
B30: BA / Requirements Review
B31: QA Strategy Review | C31: In progress
B32: DevOps / Infra Review
B33: Estimation Peer Review
B34: Final Sign-off (DM/PM)
A36: Mandatory calculations
B37: Calculation | C37: Value | D37: Source
B38: Discovery Phase Profitability (if any) | D38: Internal Cost & Profitability
B39: Proposed solution price profitability | D39: Internal Cost & Profitability
B40: Seniority Index | D40: Internal Cost & Profitability
B41: Total Hours (Build) | D41: Headcount and Cost
B42: Total Hours (Maintenance, monthly) | D42: Maintenance
B43: Total Cost (Build) | D43: Headcount and Cost
B44: Project Duration (weeks) | D44: Headcount and Cost
...

Sheet Solution Context & Sizing
A1: Solution Context & Sizing
A2: Purpose: | B2: Records the assumptions the estimate is conditioned on. If any of these change materially after the SOW is signed, the estimate must be revisited.
A3: How to use: | B3: Fill the Value column for each parameter. Discuss with the client; if a parameter is unknown, mark it 'TBD' and add it to the top risks. Use this tab as the cover sheet of the estimate when sharing externally.
A4: Inputs: | B4: Manual values from estimator + client conversations.
A5: Outputs: | B5: An immutable record of the scoping context at the moment the estimate was made.
A6: Linked tabs: | B6: Drives Apply Contingency = Yes decisions on every Est tab. Top risks here become the contingency drivers there.
A8: Section | B8: Parameter | C8: Value / description | D8: Notes
A9: Scope | B9: Products | D9: e.g. 1 product (eWallet, marketplace, ...)
A10: Scope | B10: Customers / customer categories | D10: B2C / B2B / Internal
A11: Scope | B11: User roles | D11: e.g. End-user, Business user, Admin
A12: Scope | B12: Channels | D12: Web, iOS, Android, integrations
A13: Scope | B13: Domain logic complexity | D13: Simple CRUD / Domain heavy / Regulated
A14: Scope | B14: Integrations (count) | D14: 5-15 integrations, list known ones
A15: Scope | B15: Vendor / 3rd-party products | D15: Set up by vendor or by us?
A16: Scope | B16: Major features (epics) | D16: 10-15 epics typical
A17: Infra | B17: Infrastructure model | D17: Public cloud / On-prem / Hybrid / Multi-region
A18: Infra | B18: Data residency / compliance | D18: GDPR, HIPAA, PCI-DSS, SoX, ...
A19: Infra | B19: Expected load | D19: users, RPS, data volume
A20: Infra | B20: Availability target | D20: SLA, RTO, RPO
... A24: Risks | B24: Top 3 estimation risks | D24: drives per-line Apply Contingency = Yes
A25: Risks | B25: Known unknowns
A26: Risks | B26: Hard assumptions | D26: things we believe but did not verify

Sheet WBS and Estimates
A1: WBS and Estimates
A2: Purpose: | B2: The product WBS — Epic > User Story hierarchy with PERT 3-point estimates for Back-End and Front-End. Per-row metadata makes the estimate defensible: every row carries an Include flag, Project Phase, Milestone, Assumptions, Description, Out of Scope, Dependencies, Comments and Jira link.
A3: How to use: | B3: (1) Add Section / Epic / User Story rows. Use stable IDs (E-1, US-1.3) — Epic Weight and WBS Comparison match by ID prefix. (2) Per US row, enter O / ML / P in hours for BE and FE. Augmented columns auto-add UnitTest+IntegrationTest+CodeReview. Expected, StdDev and Variance are PERT-derived. (3) Set Apply Contingency = Yes only on rows where you want to load extra hours; enter Contingency BE / FE manually. (4) Pick Include (Included / Not included / Post-MVP / Select), Phase, Milestone. (5) Fill Assumptions / Description / Out of Scope / Dependencies / Comments / Jira link. (6) Validation will highlight rows in ORANGE if P/O > 5 or O>ML>P — fix or comment.
A4: Inputs: | B4: O / ML / P per row (hours). Include / Phase / Milestone / Apply Contingency / Contingency BE/FE / metadata.
A5: Outputs: | B5: Expected BE / FE per row, StdDev/Variance per row. Sums of P (col P, BE Expected) and Q (FE Expected), and S/U (variance) feed Buffers & Non-Dev Activities.
A6: Linked tabs: | B6: Buffers & Non-Dev Activities (consumes Expected and Variance). Epic Weight (groups by ID prefix). WBS Comparison (joins by ID). Headcount and Cost (via Buffers totals).
A7: Hierarchy | B7: ID | C7: Decomposition Item | D7: Backend, h | G7: Frontend, h | J7: Augmented Backend, h | M7: Augmented Frontend, h | P7: Expected Implementation Back-End (man/h) | Q7: Expected Implementation Front-End (man/h) | R7: StdDev BE | S7: Variance BE | T7: StdDev FE | U7: Variance FE | V7: Apply Contingency | W7: Contingency, h (BE) | X7: Contingency, h (FE) | Y7: Include | Z7: Project Phase | AA7: Milestone | AB7: Assumptions | AC7: Description / Scope | AD7: Out of Scope | AE7: Dependencies | AF7: Comments | AG7: Jira / Ticket Link
A8: Hierarchy | B8: ID | C8: Decomposition Item | D8: O | E8: ML | F8: P | G8: O | H8: ML | I8: P | J8: Augmented O | K8: Augmented ML | L8: Augmented P | M8: Augmented O | N8: Augmented ML | O8: Augmented P | P8: Expected BE | Q8: Expected FE | R8: StdDev BE | S8: Variance BE | T8: StdDev FE | U8: Variance FE | V8: Apply Contingency | W8: Contingency BE | X8: Contingency FE | Y8: Include | Z8: Phase | AA8: Milestone | AB8: Assumptions | AC8: Description / Scope | AD8: Out of Scope | AE8: Dependencies | AF8: Comments | AG8: Jira / Ticket Link
A9: Section | C9: Infrastructure & Foundations
A10: UserStory | B10: INF-1.1 | C10: Solution setup (repos, project templates) | D10: 8 | E10: 16 | F10: 32 | G10: 6 | H10: 12 | I10: 20 | J10: =D10*(1+RefUnitTest+RefIntegrationTest+RefCodeReview) | K10: =E10*(1+RefUnitTest+RefIntegrationTest+RefCodeReview) | L10: =F10*(1+RefUnitTest+RefIntegrationTest+RefCodeReview) | M10: =G10*(1+RefUnitTest+RefIntegrationTest+RefCodeReview) | N10: =H10*(1+RefUnitTest+RefIntegrationTest+RefCodeReview) | O10: =I10*(1+RefUnitTest+RefIntegrationTest+RefCodeReview) | P10: =(J10+4*K10+L10)/6 | Q10: =(M10+4*N10+O10)/6 | R10: =(L10-J10)/6 | S10: =R10^2 | T10: =(O10-M10)/6 | U10: =T10^2 | V10: No | W10: 0 | X10: 0 | Y10: Included | Z10: Implementation | AA10: M1 | AC10: Bootstrap repositories, project templates, CI seed
A11: UserStory | B11: INF-1.2 | C11: Local infrastructure setup | D11: 0 | E11: 0 | F11: 0 | G11: 0 | H11: 0 | I11: 0 | J11: =D11*(1+RefUnitTest+RefIntegrationTest+RefCodeReview) | K11: =E11*(1+RefUnitTest+RefIntegrationTest+RefCodeReview) | L11: =F11*(1+RefUnitTest+RefIntegrationTest+RefCodeReview) | M11: =G11*(1+RefUnitTest+RefIntegrationTest+RefCodeReview) | N11: =H11*(1+RefUnitTest+RefIntegrationTest+RefCodeReview) | O11: =I11*(1+RefUnitTest+RefIntegrationTest+RefCodeReview) | P11: =(J11+4*K11+L11)/6 | Q11: =(M11+4*N11+O11)/6 | R11: =(L11-J11)/6 | S11: =R11^2 | T11: =(O11-M11)/6 | U11: =T11^2 | V11: No | W11: 0 | X11: 0 | Y11: Not included | Z11: Implementation | AA11: M1 | AF11: Covered in DevOps tab
A12: UserStory | B12: INF-1.3 | C12: CI/CD setup | D12: 0 | E12: 0 | F12: 0 | G12: 0 | H12: 0 | I12: 0 | J12: =D12*(1+RefUnitTest+RefIntegrationTest+RefCodeReview) | K12: =E12*(1+RefUnitTest+RefIntegrationTest+RefCodeReview) | L12: =F12*(1+RefUnitTest+RefIntegrationTest+RefCodeReview) | M12: =G12*(1+RefUnitTest+RefIntegrationTest+RefCodeReview) | N12: =H12*(1+RefUnitTest+RefIntegrationTest+RefCodeReview) | O12: =I12*(1+RefUnitTest+RefIntegrationTest+RefCodeReview) | P12: =(J12+4*K12+L12)/6 | Q12: =(M12+4*N12+O12)/6 | R12: =(L12-J12)/6 | S12: =R12^2 | T12: =(O12-M12)/6 | U12: =T12^2 | V12: No | W12: 0 | X12: 0 | Y12: Not included | Z12: Implementation | AA12: M1 | AE12: DevOps | AF12: Covered in DevOps tab
A13: UserStory | B13: INF-1.4 | C13: Static code analysis | D13: 0 | E13: 0 | F13: 0 | G13: 0 | H13: 0 | I13: 0 | J13: =D13*(1+RefUnitTest+RefIntegrationTest+RefCodeReview) | K13: =E13*(1+RefUnitTest+RefIntegrationTest+RefCodeReview) | L13: =F13*(1+RefUnitTest+RefIntegrationTest+RefCodeReview) | M13: =G13*(1+RefUnitTest+RefIntegrationTest+RefCodeReview) | N13: =H13*(1+RefUnitTest+RefIntegrationTest+RefCodeReview) | O13: =I13*(1+RefUnitTest+RefIntegrationTest+RefCodeReview) | P13: =(J13+4*K13+L13)/6 | Q13: =(M13+4*N13+O13)/6 | R13: =(L13-J13)/6 | S13: =R13^2 | T13: =(O13-M13)/6 | U13: =T13^2 | V13: No | W13: 0 | X13: 0 | Y13: Not included | Z13: Implementation | AA13: M1 | AF13: Covered in DevOps tab
A14: Section | C14: Product Scope
A15: Epic | B15: E-1 | C15: Authorization
A16: UserStory | B16: US-1.1 | C16: Onboarding | D16: 0 | E16: 0 | F16: 0 | G16: 2 | H16: 8 | I16: 16 | J16: =D16*(1+RefUnitTest+RefIntegrationTest+RefCodeReview) | K16: =E16*(1+RefUnitTest+RefIntegrationTest+RefCodeReview) | L16: =F16*(1+RefUnitTest+RefIntegrationTest+RefCodeReview) | M16: =G16*(1+RefUnitTest+RefIntegrationTest+RefCodeReview) | N16: =H16*(1+RefUnitTest+RefIntegrationTest+RefCodeReview) | O16: =I16*(1+RefUnitTest+RefIntegrationTest+RefCodeReview) | P16: =(J16+4*K16+L16)/6 | Q16: =(M16+4*N16+O16)/6 | R16: =(L16-J16)/6 | S16: =R16^2 | T16: =(O16-M16)/6 | U16: =T16^2 | V16: No | W16: 0 | X16: 0 | Y16: Included | Z16: Implementation | AA16: M1
A17: UserStory | B17: US-1.2 | C17: Accept Terms of Use | D17: 0 | E17: 0 | F17: 0 | G17: 1 | H17: 3 | I17: 4 | J17: =D17*(1+RefUnitTest+RefIntegrationTest+RefCodeReview) | K17: =E17*(1+RefUnitTest+RefIntegrationTest+RefCodeReview) | L17: =F17*(1+RefUnitTest+RefIntegrationTest+RefCodeReview) | M17: =G17*(1+RefUnitTest+RefIntegrationTest+RefCodeReview) | N17: =H17*(1+RefUnitTest+RefIntegrationTest+RefCodeReview) | O17: =I17*(1+RefUnitTest+RefIntegrationTest+RefCodeReview) | P17: =(J17+4*K17+L17)/6 | Q17: =(M17+4*N17+O17)/6 | R17: =(L17-J17)/6 | S17: =R17^2 | T17: =(O17-M17)/6 | U17: =T17^2 | V17: No | W17: 0 | X17: 0 | Y17: Included | Z17: Implementation | AA17: M1
A18: UserStory | B18: US-1.3 | C18: Sign Up (email/phone/SSO) | D18: 16 | E18: 24 | F18: 32 | G18: 16 | H18: 24 | I18: 32 | J18: =D18*(1+RefUnitTest+RefIntegrationTest+RefCodeReview) | K18: =E18*(1+RefUnitTest+RefIntegrationTest+RefCodeReview) | L18: =F18*(1+RefUnitTest+RefIntegrationTest+RefCodeReview) | M18: =G18*(1+RefUnitTest+RefIntegrationTest+RefCodeReview) | N18: =H18*(1+RefUnitTest+RefIntegrationTest+RefCodeReview) | O18: =I18*(1+RefUnitTest+RefIntegrationTest+RefCodeReview) | P18: =(J18+4*K18+L18)/6 | Q18: =(M18+4*N18+O18)/6 | R18: =(L18-J18)/6 | S18: =R18^2 | T18: =(O18-M18)/6 | U18: =T18^2 | V18: No | W18: 0 | X18: 0 | Y18: Included | Z18: Implementation | AA18: M1 | AB18: Google/Microsoft/Apple SSO
A19: UserStory | B19: US-1.4 | C19: Login | D19: 8 | E19: 16 | F19: 24 | G19: 8 | H19: 16 | I19: 24 | J19: =D19*(1+RefUnitTest+RefIntegrationTest+RefCodeReview) | K19: =E19*(1+RefUnitTest+RefIntegrationTest+RefCodeReview) | L19: =F19*(1+RefUnitTest+RefIntegrationTest+RefCodeReview) | M19: =G19*(1+RefUnitTest+RefIntegrationTest+RefCodeReview) | N19: =H19*(1+RefUnitTest+RefIntegrationTest+RefCodeReview) | O19: =I19*(1+RefUnitTest+RefIntegrationTest+RefCodeReview) | P19: =(J19+4*K19+L19)/6 | Q19: =(M19+4*N19+O19)/6 | R19: =(L19-J19)/6 | S19: =R19^2 | T19: =(O19-M19)/6 | U19: =T19^2 | V19: No | W19: 0 | X19: 0 | Y19: Included | Z19: Implementation | AA19: M1
A20: UserStory | B20: US-1.5 | C20: Reset password | D20: 8 | E20: 16 | F20: 24 | G20: 4 | H20: 8 | I20: 16 | J20: =D20*(1+RefUnitTest+RefIntegrationTest+RefCodeReview) | K20: =E20*(1+RefUnitTest+RefIntegrationTest+RefCodeReview) | L20: =F20*(1+RefUnitTest+RefIntegrationTest+RefCodeReview) | M20: =G20*(1+RefUnitTest+RefIntegrationTest+RefCodeReview) | N20: =H20*(1+RefUnitTest+RefIntegrationTest+RefCodeReview) | O20: =I20*(1+RefUnitTest+RefIntegrationTest+RefCodeReview) | P20: =(J20+4*K20+L20)/6 | Q20: =(M20+4*N20+O20)/6 | R20: =(L20-J20)/6 | S20: =R20^2 | T20: =(O20-M20)/6 | U20: =T20^2 | V20: No | W20: 0 | X20: 0 | Y20: Included | Z20: Implementation | AA20: M1
A21: UserStory | B21: US-1.6 | C21: Logout | D21: 2 | E21: 4 | F21: 8 | G21: 2 | H21: 4 | I21: 8 | J21: =D21*(1+RefUnitTest+RefIntegrationTest+RefCodeReview) | K21: =E21*(1+RefUnitTest+RefIntegrationTest+RefCodeReview) | L21: =F21*(1+RefUnitTest+RefIntegrationTest+RefCodeReview) | M21: =G21*(1+RefUnitTest+RefIntegrationTest+RefCodeReview) | N21: =H21*(1+RefUnitTest+RefIntegrationTest+RefCodeReview) | O21: =I21*(1+RefUnitTest+RefIntegrationTest+RefCodeReview) | P21: =(J21+4*K21+L21)/6 | Q21: =(M21+4*N21+O21)/6 | R21: =(L21-J21)/6 | S21: =R21^2 | T21: =(O21-M21)/6 | U21: =T21^2 | V21: No | W21: 0 | X21: 0 | Y21: Included | Z21: Implementation | AA21: M1
A22: UserStory | B22: US-1.7 | C22: 2FA setup | D22: 16 | E22: 32 | F22: 48 | G22: 8 | H22: 16 | I22: 24 | J22: =D22*(1+RefUnitTest+RefIntegrationTest+RefCodeReview) | K22: =E22*(1+RefUnitTest+RefIntegrationTest+RefCodeReview) | L22: =F22*(1+RefUnitTest+RefIntegrationTest+RefCodeReview) | M22: =G22*(1+RefUnitTest+RefIntegrationTest+RefCodeReview) | N22: =H22*(1+RefUnitTest+RefIntegrationTest+RefCodeReview) | O22: =I22*(1+RefUnitTest+RefIntegrationTest+RefCodeReview) | P22: =(J22+4*K22+L22)/6 | Q22: =(M22+4*N22+O22)/6 | R22: =(L22-J22)/6 | S22: =R22^2 | T22: =(O22-M22)/6 | U22: =T22^2 | V22: No | W22: 0 | X22: 0 | Y22: Included | Z22: Implementation | AA22: M2 | AB22: TOTP via authenticator + SMS fallback
A23: Epic | B23: E-2 | C23: Profile Management
A24: UserStory | B24: US-2.1 | C24: View profile info | D24: 4 | E24: 8 | F24: 16 | G24: 4 | H24: 8 | I24: 12 | J24: =D24*(1+RefUnitTest+RefIntegrationTest+RefCodeReview) | K24: =E24*(1+RefUnitTest+RefIntegrationTest+RefCodeReview) | L24: =F24*(1+RefUnitTest+RefIntegrationTest+RefCodeReview) | M24: =G24*(1+RefUnitTest+RefIntegrationTest+RefCodeReview) | N24: =H24*(1+RefUnitTest+RefIntegrationTest+RefCodeReview) | O24: =I24*(1+RefUnitTest+RefIntegrationTest+RefCodeReview) | P24: =(J24+4*K24+L24)/6 | Q24: =(M24+4*N24+O24)/6 | R24: =(L24-J24)/6 | S24: =R24^2 | T24: =(O24-M24)/6 | U24: =T24^2 | V24: No | W24: 0 | X24: 0 | Y24: Included | Z24: Implementation | AA24: M1
A25: UserStory | B25: US-2.2 | C25: Edit personal details | D25: 8 | E25: 16 | F25: 24 | G25: 12 | H25: 20 | I25: 32 | J25: =D25*(1+RefUnitTest+RefIntegrationTest+RefCodeReview) | K25: =E25*(1+RefUnitTest+RefIntegrationTest+RefCodeReview) | L25: =F25*(1+RefUnitTest+RefIntegrationTest+RefCodeReview) | M25: =G25*(1+RefUnitTest+RefIntegrationTest+RefCodeReview) | N25: =H25*(1+RefUnitTest+RefIntegrationTest+RefCodeReview) | O25: =I25*(1+RefUnitTest+RefIntegrationTest+RefCodeReview) | P25: =(J25+4*K25+L25)/6 | Q25: =(M25+4*N25+O25)/6 | R25: =(L25-J25)/6 | S25: =R25^2 | T25: =(O25-M25)/6 | U25: =T25^2 | V25: No | W25: 0 | X25: 0 | Y25: Included | Z25: Implementation | AA25: M1
A26: UserStory | B26: US-2.3 | C26: Change password | D26: 4 | E26: 8 | F26: 16 | G26: 4 | H26: 8 | I26: 12 | J26: =D26*(1+RefUnitTest+RefIntegrationTest+RefCodeReview) | K26: =E26*(1+RefUnitTest+RefIntegrationTest+RefCodeReview) | L26: =F26*(1+RefUnitTest+RefIntegrationTest+RefCodeReview) | M26: =G26*(1+RefUnitTest+RefIntegrationTest+RefCodeReview) | N26: =H26*(1+RefUnitTest+RefIntegrationTest+RefCodeReview) | O26: =I26*(1+RefUnitTest+RefIntegrationTest+RefCodeReview) | P26: =(J26+4*K26+L26)/6 | Q26: =(M26+4*N26+O26)/6 | R26: =(L26-J26)/6 | S26: =R26^2 | T26: =(O26-M26)/6 | U26: =T26^2 | V26: No | W26: 0 | X26: 0 | Y26: Included | Z26: Implementation | AA26: M1
A27: UserStory | B27: US-2.4 | C27: Manage notification preferences | D27: 8 | E27: 16 | F27: 24 | G27: 4 | H27: 8 | I27: 12 | J27: =D27*(1+RefUnitTest+RefIntegrationTest+RefCodeReview) | K27: =E27*(1+RefUnitTest+RefIntegrationTest+RefCodeReview) | L27: =F27*(1+RefUnitTest+RefIntegrationTest+RefCodeReview) | M27: =G27*(1+RefUnitTest+RefIntegrationTest+RefCodeReview) | N27: =H27*(1+RefUnitTest+RefIntegrationTest+RefCodeReview) | O27: =I27*(1+RefUnitTest+RefIntegrationTest+RefCodeReview) | P27: =(J27+4*K27+L27)/6 | Q27: =(M27+4*N27+O27)/6 | R27: =(L27-J27)/6 | S27: =R27^2 | T27: =(O27-M27)/6 | U27: =T27^2 | V27: No | W27: 0 | X27: 0 | Y27: Included | Z27: Implementation | AA27: M2
A28: UserStory | B28: US-2.5 | C28: Delete account | D28: 8 | E28: 16 | F28: 24 | G28: 4 | H28: 8 | I28: 12 | J28: =D28*(1+RefUnitTest+RefIntegrationTest+RefCodeReview) | K28: =E28*(1+RefUnitTest+RefIntegrationTest+RefCodeReview) | L28: =F28*(1+RefUnitTest+RefIntegrationTest+RefCodeReview) | M28: =G28*(1+RefUnitTest+RefIntegrationTest+RefCodeReview) | N28: =H28*(1+RefUnitTest+RefIntegrationTest+RefCodeReview) | O28: =I28*(1+RefUnitTest+RefIntegrationTest+RefCodeReview) | P28: =(J28+4*K28+L28)/6 | Q28: =(M28+4*N28+O28)/6 | R28: =(L28-J28)/6 | S28: =R28^2 | T28: =(O28-M28)/6 | U28: =T28^2 | V28: No | W28: 0 | X28: 0 | Y28: Included | Z28: Implementation | AA28: M2
A29: Epic | B29: E-3 | C29: Wallet (sample regulated/financial epic)
A30: UserStory | B30: US-3.1 | C30: Setup wallet | D30: 16 | E30: 24 | F30: 40 | G30: 24 | H30: 40 | I30: 60 | J30: =D30*(1+RefUnitTest+RefIntegrationTest+RefCodeReview) | K30: =E30*(1+RefUnitTest+RefIntegrationTest+RefCodeReview) | L30: =F30*(1+RefUnitTest+RefIntegrationTest+RefCodeReview) | M30: =G30*(1+RefUnitTest+RefIntegrationTest+RefCodeReview) | N30: =H30*(1+RefUnitTest+RefIntegrationTest+RefCodeReview) | O30: =I30*(1+RefUnitTest+RefIntegrationTest+RefCodeReview) | P30: =(J30+4*K30+L30)/6 | Q30: =(M30+4*N30+O30)/6 | R30: =(L30-J30)/6 | S30: =R30^2 | T30: =(O30-M30)/6 | U30: =T30^2 | V30: No | W30: 0 | X30: 0 | Y30: Included | Z30: Implementation | AA30: M2 | AB30: custodial wallet, KMS-backed
A31: UserStory | B31: US-3.2 | C31: Buy tokens | D31: 16 | E31: 24 | F31: 40 | G31: 12 | H31: 20 | I31: 32 | J31: =D31*(1+RefUnitTest+RefIntegrationTest+RefCodeReview) | K31: =E31*(1+RefUnitTest+RefIntegrationTest+RefCodeReview) | L31: =F31*(1+RefUnitTest+RefIntegrationTest+RefCodeReview) | M31: =G31*(1+RefUnitTest+RefIntegrationTest+RefCodeReview) | N31: =H31*(1+RefUnitTest+RefIntegrationTest+RefCodeReview) | O31: =I31*(1+RefUnitTest+RefIntegrationTest+RefCodeReview) | P31: =(J31+4*K31+L31)/6 | Q31: =(M31+4*N31+O31)/6 | R31: =(L31-J31)/6 | S31: =R31^2 | T31: =(O31-M31)/6 | U31: =T31^2 | V31: No | W31: 0 | X31: 0 | Y31: Included | Z31: Implementation | AA31: M2 | AB31: Stripe + crypto on-ramp
A32: UserStory | B32: US-3.3 | C32: Sell tokens | D32: 16 | E32: 24 | F32: 40 | G32: 8 | H32: 12 | I32: 24 | J32: =D32*(1+RefUnitTest+RefIntegrationTest+RefCodeReview) | K32: =E32*(1+RefUnitTest+RefIntegrationTest+RefCodeReview) | L32: =F32*(1+RefUnitTest+RefIntegrationTest+RefCodeReview) | M32: =G32*(1+RefUnitTest+RefIntegrationTest+RefCodeReview) | N32: =H32*(1+RefUnitTest+RefIntegrationTest+RefCodeReview) | O32: =I32*(1+RefUnitTest+RefIntegrationTest+RefCodeReview) | P32: =(J32+4*K32+L32)/6 | Q32: =(M32+4*N32+O32)/6 | R32: =(L32-J32)/6 | S32: =R32^2 | T32: =(O32-M32)/6 | U32: =T32^2 | V32: No | W32: 0 | X32: 0 | Y32: Included | Z32: Implementation | AA32: M3
A33: UserStory | B33: US-3.4 | C33: View transactions | D33: 12 | E33: 20 | F33: 32 | G33: 12 | H33: 16 | I33: 24 | J33: =D33*(1+RefUnitTest+RefIntegrationTest+RefCodeReview) | K33: =E33*(1+RefUnitTest+RefIntegrationTest+RefCodeReview) | L33: =F33*(1+RefUnitTest+RefIntegrationTest+RefCodeReview) | M33: =G33*(1+RefUnitTest+RefIntegrationTest+RefCodeReview) | N33: =H33*(1+RefUnitTest+RefIntegrationTest+RefCodeReview) | O33: =I33*(1+RefUnitTest+RefIntegrationTest+RefCodeReview) | P33: =(J33+4*K33+L33)/6 | Q33: =(M33+4*N33+O33)/6 | R33: =(L33-J33)/6 | S33: =R33^2 | T33: =(O33-M33)/6 | U33: =T33^2 | V33: No | W33: 0 | X33: 0 | Y33: Included | Z33: Implementation | AA33: M2
A34: UserStory | B34: US-3.5 | C34: KYC initiate / upload ID / verify | D34: 16 | E34: 32 | F34: 64 | G34: 8 | H34: 16 | I34: 24 | J34: =D34*(1+RefUnitTest+RefIntegrationTest+RefCodeReview) | K34: =E34*(1+RefUnitTest+RefIntegrationTest+RefCodeReview) | L34: =F34*(1+RefUnitTest+RefIntegrationTest+RefCodeReview) | M34: =G34*(1+RefUnitTest+RefIntegrationTest+RefCodeReview) | N34: =H34*(1+RefUnitTest+RefIntegrationTest+RefCodeReview) | O34: =I34*(1+RefUnitTest+RefIntegrationTest+RefCodeReview) | P34: =(J34+4*K34+L34)/6 | Q34: =(M34+4*N34+O34)/6 | R34: =(L34-J34)/6 | S34: =R34^2 | T34: =(O34-M34)/6 | U34: =T34^2 | V34: No | W34: 0 | X34: 0 | Y34: Included | Z34: Implementation | AA34: M3 | AB34: 3rd-party KYC vendor (Onfido/SumSub)

Sheet BA Estimation
A1: Business Analysis Estimation
A2: Purpose: | B2: Catalogue of BA deliverables (Vision & Scope, USM, RACI, BPMN, Class diagrams, prototypes, benchmarking, ...) with PERT estimates per item. Replaces the v1.4 assumption that BA effort equals 0.25 FTE.
A3: How to use: | B3: (1) Walk down the catalogue. (2) Set O/ML/P for items you'll deliver, leave others at 0. (3) Set Include = Not included for items the client did not buy (they stay in the catalogue but excluded from totals). (4) Use Apply Contingency = Yes on items with vague requirements (typical 20% default). (5) Mark Phase = Discovery / Implementation / Post-MVP / Maintenance.
A4: Inputs: | B4: O/ML/P per row, Apply Contingency Y/N, Include, Phase, Deliverable, Description, Assumptions, Notes.
A5: Outputs: | B5: Final Expected per row. Included sum (col I where Include=Included) flows to Buffers & Non-Dev Activities and from there to Headcount and Cost as the BA estimated hours.
A6: Linked tabs: | B6: Buffers & Non-Dev Activities (BA roll-up). Headcount and Cost (BA estimated hours).
A7: Default contingency: | B7: 0.2 | C7: (used when Apply Contingency = Yes; multiplied by Most Likely)
A8: Per-line PERT estimate for BA deliverables. Default contingency 20% applied when Apply Contingency = Yes.
A10: ID | B10: Service / Activity | C10: Optimistic | D10: Most Likely | E10: Pessimistic | F10: Expected | G10: Apply Contingency | H10: Contingency | I10: Final Expected | J10: Include | K10: Project Phase | L10: Deliverable | M10: Description / Scope | N10: Assumptions | O10: Notes
B11: TOTALS | C11: =SUM(C12:C29) | D11: =SUM(D12:D29) | E11: =SUM(E12:E29) | F11: =SUM(F12:F29) | H11: =SUM(H12:H29) | I11: =SUMIF(J12:J29,"Included",I12:I29) | J11: (only Included counted at right)
A12: BA-1 | B12: Discovery deliverables
A13: BA-1.1 | B13: Vision & Scope document | C13: 8 | D13: 16 | E13: 24 | F13: =IF(AND(C13<>"",D13<>"",E13<>""),(C13+4*D13+E13)/6,0) | G13: Yes | H13: =IF(G13="Yes",ROUND(D13*$B$7,1),0) | I13: =F13+H13 | J13: Included | K13: Discovery | L13: Vision & Scope doc | M13: Background, Business Opportunity, Objectives, Risks, Vision Statement, Major Features, Assumptions, Stakeholder Profiles, Operating Environment, Glossary
A14: BA-1.2 | B14: User Story Map (USM) | C14: 16 | D14: 32 | E14: 48 | F14: =IF(AND(C14<>"",D14<>"",E14<>""),(C14+4*D14+E14)/6,0) | G14: Yes | H14: =IF(G14="Yes",ROUND(D14*$B$7,1),0) | I14: =F14+H14 | J14: Included | K14: Discovery | L14: USM | M14: Visualization of the product backbone across user journey
A15: BA-1.3 | B15: Roles & Permissions Matrix | C15: 8 | D15: 12 | E15: 20 | F15: =IF(AND(C15<>"",D15<>"",E15<>""),(C15+4*D15+E15)/6,0) | G15: Yes | H15: =IF(G15="Yes",ROUND(D15*$B$7,1),0) | I15: =F15+H15 | J15: Included | K15: Discovery | L15: RBAC matrix | M15: Roles, role-related features, permission grid
A16: BA-1.4 | B16: WBS / Feature list adjustment | C16: 4 | D16: 8 | E16: 16 | F16: =IF(AND(C16<>"",D16<>"",E16<>""),(C16+4*D16+E16)/6,0) | G16: No | H16: =IF(G16="Yes",ROUND(D16*$B$7,1),0) | I16: =F16+H16 | J16: Included | K16: Discovery | L16: MVP / Post-MVP feature list
A17: BA-1.5 | B17: Initial Sprint Backlog | C17: 16 | D17: 24 | E17: 40 | F17: =IF(AND(C17<>"",D17<>"",E17<>""),(C17+4*D17+E17)/6,0) | G17: Yes | H17: =IF(G17="Yes",ROUND(D17*$B$7,1),0) | I17: =F17+H17 | J17: Included | K17: Discovery | L17: Initial Backlog | M17: Prioritized, DoR-ready USs for first sprints
A18: BA-1.6 | B18: BPMN diagrams (key processes) | C18: 16 | D18: 32 | E18: 48 | F18: =IF(AND(C18<>"",D18<>"",E18<>""),(C18+4*D18+E18)/6,0) | G18: Yes | H18: =IF(G18="Yes",ROUND(D18*$B$7,1),0) | I18: =F18+H18 | J18: Included | K18: Discovery | L18: BPMN diagrams
A19: BA-1.7 | B19: Interactive prototypes (key flows) | C19: 16 | D19: 24 | E19: 40 | F19: =IF(AND(C19<>"",D19<>"",E19<>""),(C19+4*D19+E19)/6,0) | G19: No | H19: =IF(G19="Yes",ROUND(D19*$B$7,1),0) | I19: =F19+H19 | J19: Not included | K19: Discovery | L19: Figma prototypes | M19: Coordinated with UI/UX tab
A20: BA-1.8 | B20: Context Diagram | C20: 8 | D20: 12 | E20: 24 | F20: =IF(AND(C20<>"",D20<>"",E20<>""),(C20+4*D20+E20)/6,0) | G20: No | H20: =IF(G20="Yes",ROUND(D20*$B$7,1),0) | I20: =F20+H20 | J20: Included | K20: Discovery | L20: Context diagram
A21: BA-1.9 | B21: Class diagram (high level) | C21: 8 | D21: 12 | E21: 24 | F21: =IF(AND(C21<>"",D21<>"",E21<>""),(C21+4*D21+E21)/6,0) | G21: No | H21: =IF(G21="Yes",ROUND(D21*$B$7,1),0) | I21: =F21+H21 | J21: Included | K21: Discovery | L21: Class diagram
A22: BA-1.10 | B22: State machine diagram | C22: 8 | D22: 16 | E22: 32 | F22: =IF(AND(C22<>"",D22<>"",E22<>""),(C22+4*D22+E22)/6,0) | G22: No | H22: =IF(G22="Yes",ROUND(D22*$B$7,1),0) | I22: =F22+H22 | J22: Included | K22: Discovery | L22: State machine
A23: BA-1.11 | B23: Benchmarking / competitor analysis | C23: 16 | D23: 32 | E23: 48 | F23: =IF(AND(C23<>"",D23<>"",E23<>""),(C23+4*D23+E23)/6,0) | G23: No | H23: =IF(G23="Yes",ROUND(D23*$B$7,1),0) | I23: =F23+H23 | J23: Not included | K23: Discovery
A24: BA-1.12 | B24: Stakeholder Matrix / Glossary / Communication plan | C24: 4 | D24: 8 | E24: 12 | F24: =IF(AND(C24<>"",D24<>"",E24<>""),(C24+4*D24+E24)/6,0) | G24: No | H24: =IF(G24="Yes",ROUND(D24*$B$7,1),0) | I24: =F24+H24 | J24: Included | K24: Discovery
A25: BA-2 | B25: Implementation deliverables
A26: BA-2.1 | B26: Refining backlog (per sprint) | C26: 4 | D26: 8 | E26: 12 | F26: =IF(AND(C26<>"",D26<>"",E26<>""),(C26+4*D26+E26)/6,0) | G26: No | H26: =IF(G26="Yes",ROUND(D26*$B$7,1),0) | I26: =F26+H26 | J26: Included | K26: Implementation | L26: Refined backlog | M26: Per sprint over implementation duration
A27: BA-2.2 | B27: Acceptance criteria authoring | C27: 4 | D27: 8 | E27: 12 | F27: =IF(AND(C27<>"",D27<>"",E27<>""),(C27+4*D27+E27)/6,0) | G27: No | H27: =IF(G27="Yes",ROUND(D27*$B$7,1),0) | I27: =F27+H27 | J27: Included | K27: Implementation
A28: BA-2.3 | B28: Change request analysis | C28: 4 | D28: 8 | E28: 16 | F28: =IF(AND(C28<>"",D28<>"",E28<>""),(C28+4*D28+E28)/6,0) | G28: Yes | H28: =IF(G28="Yes",ROUND(D28*$B$7,1),0) | I28: =F28+H28 | J28: Included | K28: Implementation
A29: BA-2.4 | B29: Demo support / UAT support | C29: 4 | D29: 8 | E29: 16 | F29: =IF(AND(C29<>"",D29<>"",E29<>""),(C29+4*D29+E29)/6,0) | G29: No | H29: =IF(G29="Yes",ROUND(D29*$B$7,1),0) | I29: =F29+H29 | J29: Included | K29: Implementation

Sheet Arch Estimation
A1: Architecture Estimation (SA + Software A)
A2: Purpose: | B2: Catalogue of architecture deliverables — Architectural Drivers (AVD), Solution Architecture views (Context/Container/Component/Deployment), Decision/Risk records, Operation plan, Implementation roadmap. 30% contingency reflects design uncertainty.
A3: How to use: | B3: (1) Per item, set O/ML/P. (2) Items left empty stay in the catalogue as a checklist of what was considered but not estimated (mark Include = Not included). (3) Use Apply Contingency = Yes for items requiring discovery workshops or third-party APIs. (4) Compliance items (OWASP, GDPR, PCI-DSS, HIPAA, SoX) are off by default — switch on if applicable.
A4: Inputs: | B4: O/ML/P per row, Apply Contingency Y/N, Include, Phase, Deliverable, Description, Assumptions.
A5: Outputs: | B5: Architecture roll-up flows to Buffers tab and then Headcount and Cost as 'Architecture (SA+SwA)' estimated hours.
A6: Linked tabs: | B6: Buffers & Non-Dev Activities (Architecture roll-up). Headcount and Cost.
A7: Default contingency: | B7: 0.3 | C7: (used when Apply Contingency = Yes; multiplied by Most Likely)
A8: Solution & Software Architecture deliverables. Higher 30% contingency reflects design uncertainty.
A10: ID | B10: Service / Activity | C10: Optimistic | D10: Most Likely | E10: Pessimistic | F10: Expected | G10: Apply Contingency | H10: Contingency | I10: Final Expected | J10: Include | K10: Project Phase | L10: Deliverable | M10: Description / Scope | N10: Assumptions | O10: Notes
B11: TOTALS | C11: =SUM(C12:C46) | D11: =SUM(D12:D46) | E11: =SUM(E12:E46) | F11: =SUM(F12:F46) | H11: =SUM(H12:H46) | I11: =SUMIF(J12:J46,"Included",I12:I46) | J11: (only Included counted at right)
A12: ARC-1 | B12: Architectural Drivers (AVD)
A13: ARC-1.1 | B13: Business Goals | C13: 2 | D13: 2.5 | E13: 3 | F13: =IF(AND(C13<>"",D13<>"",E13<>""),(C13+4*D13+E13)/6,0) | G13: No | H13: =IF(G13="Yes",ROUND(D13*$B$7,1),0) | I13: =F13+H13 | J13: Included | K13: Discovery | L13: AVD: Business Goals
A14: ARC-1.2 | B14: Major Features | C14: 2 | D14: 2.5 | E14: 3 | F14: =IF(AND(C14<>"",D14<>"",E14<>""),(C14+4*D14+E14)/6,0) | G14: No | H14: =IF(G14="Yes",ROUND(D14*$B$7,1),0) | I14: =F14+H14 | J14: Included | K14: Discovery
A15: ARC-1.3 | B15: Design Constraints | C15: 2 | D15: 2.5 | E15: 3 | F15: =IF(AND(C15<>"",D15<>"",E15<>""),(C15+4*D15+E15)/6,0) | G15: No | H15: =IF(G15="Yes",ROUND(D15*$B$7,1),0) | I15: =F15+H15 | J15: Included | K15: Discovery
A16: ARC-1.4 | B16: Architectural Concerns | C16: 2 | D16: 2.5 | E16: 3 | F16: =IF(AND(C16<>"",D16<>"",E16<>""),(C16+4*D16+E16)/6,0) | G16: No | H16: =IF(G16="Yes",ROUND(D16*$B$7,1),0) | I16: =F16+H16 | J16: Included | K16: Discovery
A17: ARC-1.5 | B17: Quality Attributes (cross-cutting) | C17: 8 | D17: 10 | E17: 12 | F17: =IF(AND(C17<>"",D17<>"",E17<>""),(C17+4*D17+E17)/6,0) | G17: Yes | H17: =IF(G17="Yes",ROUND(D17*$B$7,1),0) | I17: =F17+H17 | J17: Included | K17: Discovery | M17: Availability, Performance, Observability, Scalability, Localization, Fault Tolerance, Recoverability, Security (App + Code), Extendability, Maintainability
A18: ARC-1.6 | B18: Compliance scope (OWASP/GDPR/PCI/HIPAA/SoX) | C18: 0 | D18: 0 | E18: 0 | F18: =IF(AND(C18<>"",D18<>"",E18<>""),(C18+4*D18+E18)/6,0) | G18: No | H18: =IF(G18="Yes",ROUND(D18*$B$7,1),0) | I18: =F18+H18 | J18: Not included | K18: Discovery | M18: Estimated separately per applicable regulation
A19: ARC-2 | B19: Solution Architecture
A20: ARC-2.1 | B20: System Context View | C20: 2 | D20: 4 | E20: 6 | F20: =IF(AND(C20<>"",D20<>"",E20<>""),(C20+4*D20+E20)/6,0) | G20: No | H20: =IF(G20="Yes",ROUND(D20*$B$7,1),0) | I20: =F20+H20 | J20: Included | K20: Discovery
A21: ARC-2.2 | B21: Container View | C21: 4 | D21: 6 | E21: 8 | F21: =IF(AND(C21<>"",D21<>"",E21<>""),(C21+4*D21+E21)/6,0) | G21: No | H21: =IF(G21="Yes",ROUND(D21*$B$7,1),0) | I21: =F21+H21 | J21: Included | K21: Discovery
A22: ARC-2.3 | B22: Component View — Front-end | C22: 1 | D22: 3 | E22: 4 | F22: =IF(AND(C22<>"",D22<>"",E22<>""),(C22+4*D22+E22)/6,0) | G22: No | H22: =IF(G22="Yes",ROUND(D22*$B$7,1),0) | I22: =F22+H22 | J22: Not included | K22: Discovery
A23: ARC-2.4 | B23: Component View — Back-end | C23: 3 | D23: 6 | E23: 8 | F23: =IF(AND(C23<>"",D23<>"",E23<>""),(C23+4*D23+E23)/6,0) | G23: Yes | H23: =IF(G23="Yes",ROUND(D23*$B$7,1),0) | I23: =F23+H23 | J23: Included | K23: Discovery
A24: ARC-2.5 | B24: Epic-level architectural design | C24: 16 | D24: 18 | E24: 20 | F24: =IF(AND(C24<>"",D24<>"",E24<>""),(C24+4*D24+E24)/6,0) | G24: Yes | H24: =IF(G24="Yes",ROUND(D24*$B$7,1),0) | I24: =F24+H24 | J24: Included | K24: Discovery
A25: ARC-2.6 | B25: Deployment View | C25: 4 | D25: 8 | E25: 10 | F25: =IF(AND(C25<>"",D25<>"",E25<>""),(C25+4*D25+E25)/6,0) | G25: Yes | H25: =IF(G25="Yes",ROUND(D25*$B$7,1),0) | I25: =F25+H25 | J25: Included | K25: Discovery
A26: ARC-2.7 | B26: Decision View / ADRs | C26: 4 | D26: 6 | E26: 8 | F26: =IF(AND(C26<>"",D26<>"",E26<>""),(C26+4*D26+E26)/6,0) | G26: No | H26: =IF(G26="Yes",ROUND(D26*$B$7,1),0) | I26: =F26+H26 | J26: Not included | K26: Discovery
A27: ARC-2.8 | B27: Risk View / Risk Record | C27: 4 | D27: 6 | E27: 8 | F27: =IF(AND(C27<>"",D27<>"",E27<>""),(C27+4*D27+E27)/6,0) | G27: No | H27: =IF(G27="Yes",ROUND(D27*$B$7,1),0) | I27: =F27+H27 | J27: Included | K27: Discovery
A28: ARC-3 | B28: Operation plan
A29: ARC-3.1 | B29: Infrastructure model | C29: 2 | D29: 5 | E29: 4 | F29: =IF(AND(C29<>"",D29<>"",E29<>""),(C29+4*D29+E29)/6,0) | G29: Yes | H29: =IF(G29="Yes",ROUND(D29*$B$7,1),0) | I29: =F29+H29 | J29: Included | K29: Discovery
A30: ARC-3.2 | B30: Continuous integration / continuous delivery | C30: 2 | D30: 5 | E30: 4 | F30: =IF(AND(C30<>"",D30<>"",E30<>""),(C30+4*D30+E30)/6,0) | G30: Yes | H30: =IF(G30="Yes",ROUND(D30*$B$7,1),0) | I30: =F30+H30 | J30: Included | K30: Discovery
A31: ARC-3.3 | B31: Monitoring / Observability | C31: 2 | D31: 5 | E31: 4 | F31: =IF(AND(C31<>"",D31<>"",E31<>""),(C31+4*D31+E31)/6,0) | G31: Yes | H31: =IF(G31="Yes",ROUND(D31*$B$7,1),0) | I31: =F31+H31 | J31: Included | K31: Discovery
A32: ARC-3.4 | B32: Secure SDLC concepts | C32: 2 | D32: 5 | E32: 4 | F32: =IF(AND(C32<>"",D32<>"",E32<>""),(C32+4*D32+E32)/6,0) | G32: No | H32: =IF(G32="Yes",ROUND(D32*$B$7,1),0) | I32: =F32+H32 | J32: Included | K32: Discovery
A33: ARC-3.5 | B33: Backup & restore | C33: 2 | D33: 5 | E33: 4 | F33: =IF(AND(C33<>"",D33<>"",E33<>""),(C33+4*D33+E33)/6,0) | G33: No | H33: =IF(G33="Yes",ROUND(D33*$B$7,1),0) | I33: =F33+H33 | J33: Included | K33: Discovery
A34: ARC-4 | B34: Implementation Roadmap
A35: ARC-4.1 | B35: Implementation Milestones | C35: 2 | D35: 3 | E35: 4 | F35: =IF(AND(C35<>"",D35<>"",E35<>""),(C35+4*D35+E35)/6,0) | G35: No | H35: =IF(G35="Yes",ROUND(D35*$B$7,1),0) | I35: =F35+H35 | J35: Included | K35: Discovery
A36: ARC-4.2 | B36: Development technology stack | C36: 1 | D36: 1.5 | E36: 2 | F36: =IF(AND(C36<>"",D36<>"",E36<>""),(C36+4*D36+E36)/6,0) | G36: No | H36: =IF(G36="Yes",ROUND(D36*$B$7,1),0) | I36: =F36+H36 | J36: Included | K36: Discovery
A37: ARC-4.3 | B37: Estimation: structure & validation | C37: 8 | D37: 11 | E37: 10 | F37: =IF(AND(C37<>"",D37<>"",E37<>""),(C37+4*D37+E37)/6,0) | G37: No | H37: =IF(G37="Yes",ROUND(D37*$B$7,1),0) | I37: =F37+H37 | J37: Included | K37: Discovery
A38: ARC-4.4 | B38: Development team skillset | C38: 1 | D38: 1.5 | E38: 2 | F38: =IF(AND(C38<>"",D38<>"",E38<>""),(C38+4*D38+E38)/6,0) | G38: No | H38: =IF(G38="Yes",ROUND(D38*$B$7,1),0) | I38: =F38+H38 | J38: Included | K38: Discovery
A39: ARC-5 | B39: Discovery workshops
A40: ARC-5.1 | B40: Discovery questions preparation | C40: 8 | D40: 12 | E40: 16 | F40: =IF(AND(C40<>"",D40<>"",E40<>""),(C40+4*D40+E40)/6,0) | G40: Yes | H40: =IF(G40="Yes",ROUND(D40*$B$7,1),0) | I40: =F40+H40 | J40: Included | K40: Discovery
A41: ARC-5.2 | B41: AVD draft / 1st review | C41: 8 | D41: 12 | E41: 16 | F41: =IF(AND(C41<>"",D41<>"",E41<>""),(C41+4*D41+E41)/6,0) | G41: No | H41: =IF(G41="Yes",ROUND(D41*$B$7,1),0) | I41: =F41+H41 | J41: Included | K41: Discovery
...

Sheet QA Estimation
A1: QA Estimation (per stream)
A2: Purpose: | B2: Defensible QA WBS split by stream: Front-end / Back-end / Mobile / Automation. Each stream covers System Config, Test Env, Strategy, Test Data, Test Case Design, Functional, Non-functional, Database, Change-related (Smoke/Regression), Test Closure.
A3: How to use: | B3: (1) Per stream, fill O/ML/P for activities relevant to your project. (2) Disable streams that don't apply by setting Include = Not included on every row of that stream. (3) Automation block defaults to Post-MVP — switch to Included if AQA is in scope for build. (4) The Buffers tab pulls the QA Estimation Included sum and uses it instead of the 15% MQA coefficient when populated; otherwise it falls back to the coefficient-based MQA/AQA derivation.
A4: Inputs: | B4: O/ML/P per row, Apply Contingency Y/N, Include, Phase, Deliverable, Description.
A5: Outputs: | B5: QA roll-up (per-stream and total). Feeds Buffers tab QA row.
A6: Linked tabs: | B6: Buffers & Non-Dev Activities (QA from this tab vs MQA/AQA coefficient). Headcount and Cost (Manual QA / AQA estimated hours).
A7: Default contingency: | B7: 0.15 | C7: (used when Apply Contingency = Yes; multiplied by Most Likely)
A8: Streams: FE / BE / Mobile / Automation. Use this tab for a defensible per-stream QA WBS in addition to (or in place of) the flat 15% coefficient from v1.4.
A10: ID | B10: Service / Activity | C10: Optimistic | D10: Most Likely | E10: Pessimistic | F10: Expected | G10: Apply Contingency | H10: Contingency | I10: Final Expected | J10: Include | K10: Project Phase | L10: Deliverable | M10: Description / Scope | N10: Assumptions | O10: Notes
B11: TOTALS | C11: =SUM(C12:C49) | D11: =SUM(D12:D49) | E11: =SUM(E12:E49) | F11: =SUM(F12:F49) | H11: =SUM(H12:H49) | I11: =SUMIF(J12:J49,"Included",I12:I49) | J11: (only Included counted at right)
A12: QA-FE | B12: QA — Front-end stream
A13: QA-FE.1 | B13: System Configuration | C13: 5 | D13: 6 | E13: 7 | F13: =IF(AND(C13<>"",D13<>"",E13<>""),(C13+4*D13+E13)/6,0) | G13: No | H13: =IF(G13="Yes",ROUND(D13*$B$7,1),0) | I13: =F13+H13 | J13: Included | K13: Discovery | L13: Task / bug-tracking config
A14: QA-FE.2 | B14: Test Environment Setup | C14: 6 | D14: 8 | E14: 12 | F14: =IF(AND(C14<>"",D14<>"",E14<>""),(C14+4*D14+E14)/6,0) | G14: No | H14: =IF(G14="Yes",ROUND(D14*$B$7,1),0) | I14: =F14+H14 | J14: Included | K14: Discovery
A15: QA-FE.3 | B15: Test Strategy & Test Plan | C15: 10 | D15: 14 | E15: 18 | F15: =IF(AND(C15<>"",D15<>"",E15<>""),(C15+4*D15+E15)/6,0) | G15: Yes | H15: =IF(G15="Yes",ROUND(D15*$B$7,1),0) | I15: =F15+H15 | J15: Included | K15: Discovery | L15: Test Strategy + Test Plan
A16: QA-FE.4 | B16: Documentation Investigation | C16: 50 | D16: 60 | E16: 70 | F16: =IF(AND(C16<>"",D16<>"",E16<>""),(C16+4*D16+E16)/6,0) | G16: No | H16: =IF(G16="Yes",ROUND(D16*$B$7,1),0) | I16: =F16+H16 | J16: Included | K16: Implementation
A17: QA-FE.5 | B17: Test Data preparation | C17: 70 | D17: 90 | E17: 120 | F17: =IF(AND(C17<>"",D17<>"",E17<>""),(C17+4*D17+E17)/6,0) | G17: No | H17: =IF(G17="Yes",ROUND(D17*$B$7,1),0) | I17: =F17+H17 | J17: Included | K17: Implementation
A18: QA-FE.6 | B18: Test Case design | C18: 110 | D18: 140 | E18: 170 | F18: =IF(AND(C18<>"",D18<>"",E18<>""),(C18+4*D18+E18)/6,0) | G18: No | H18: =IF(G18="Yes",ROUND(D18*$B$7,1),0) | I18: =F18+H18 | J18: Included | K18: Implementation
A19: QA-FE.7 | B19: Functional Testing (E2E) | C19: 90 | D19: 120 | E19: 140 | F19: =IF(AND(C19<>"",D19<>"",E19<>""),(C19+4*D19+E19)/6,0) | G19: Yes | H19: =IF(G19="Yes",ROUND(D19*$B$7,1),0) | I19: =F19+H19 | J19: Included | K19: Implementation
A20: QA-FE.8 | B20: Non-functional Testing (UI/UX, Docs) | C20: 120 | D20: 130 | E20: 160 | F20: =IF(AND(C20<>"",D20<>"",E20<>""),(C20+4*D20+E20)/6,0) | G20: No | H20: =IF(G20="Yes",ROUND(D20*$B$7,1),0) | I20: =F20+H20 | J20: Included | K20: Implementation
A21: QA-FE.9 | B21: Change-related (Smoke/Regression/Critical Path) | C21: 110 | D21: 140 | E21: 160 | F21: =IF(AND(C21<>"",D21<>"",E21<>""),(C21+4*D21+E21)/6,0) | G21: Yes | H21: =IF(G21="Yes",ROUND(D21*$B$7,1),0) | I21: =F21+H21 | J21: Included | K21: Implementation
A22: QA-FE.10 | B22: Test Closure | C22: 40 | D22: 50 | E22: 65 | F22: =IF(AND(C22<>"",D22<>"",E22<>""),(C22+4*D22+E22)/6,0) | G22: No | H22: =IF(G22="Yes",ROUND(D22*$B$7,1),0) | I22: =F22+H22 | J22: Included | K22: Implementation
A23: QA-BE | B23: QA — Back-end stream
A24: QA-BE.1 | B24: System Configuration | C24: 8 | D24: 14 | E24: 16 | F24: =IF(AND(C24<>"",D24<>"",E24<>""),(C24+4*D24+E24)/6,0) | G24: No | H24: =IF(G24="Yes",ROUND(D24*$B$7,1),0) | I24: =F24+H24 | J24: Not included | K24: Discovery
A25: QA-BE.2 | B25: Test Environment Setup | C25: 8 | D25: 14 | E25: 16 | F25: =IF(AND(C25<>"",D25<>"",E25<>""),(C25+4*D25+E25)/6,0) | G25: No | H25: =IF(G25="Yes",ROUND(D25*$B$7,1),0) | I25: =F25+H25 | J25: Not included | K25: Discovery
A26: QA-BE.3 | B26: Database (data integrity, migrations) | C26: 8 | D26: 12 | E26: 14 | F26: =IF(AND(C26<>"",D26<>"",E26<>""),(C26+4*D26+E26)/6,0) | G26: No | H26: =IF(G26="Yes",ROUND(D26*$B$7,1),0) | I26: =F26+H26 | J26: Not included | K26: Discovery
A27: QA-BE.4 | B27: Documentation Investigation | C27: 160 | D27: 180 | E27: 190 | F27: =IF(AND(C27<>"",D27<>"",E27<>""),(C27+4*D27+E27)/6,0) | G27: No | H27: =IF(G27="Yes",ROUND(D27*$B$7,1),0) | I27: =F27+H27 | J27: Included | K27: Implementation
A28: QA-BE.5 | B28: Test Data preparation | C28: 140 | D28: 170 | E28: 180 | F28: =IF(AND(C28<>"",D28<>"",E28<>""),(C28+4*D28+E28)/6,0) | G28: No | H28: =IF(G28="Yes",ROUND(D28*$B$7,1),0) | I28: =F28+H28 | J28: Included | K28: Implementation
A29: QA-BE.6 | B29: Test Case design | C29: 270 | D29: 290 | E29: 330 | F29: =IF(AND(C29<>"",D29<>"",E29<>""),(C29+4*D29+E29)/6,0) | G29: No | H29: =IF(G29="Yes",ROUND(D29*$B$7,1),0) | I29: =F29+H29 | J29: Included | K29: Implementation
A30: QA-BE.7 | B30: Database Testing | C30: 190 | D30: 230 | E30: 250 | F30: =IF(AND(C30<>"",D30<>"",E30<>""),(C30+4*D30+E30)/6,0) | G30: No | H30: =IF(G30="Yes",ROUND(D30*$B$7,1),0) | I30: =F30+H30 | J30: Included | K30: Implementation
A31: QA-BE.8 | B31: Functional Testing (Integration / API) | C31: 280 | D31: 300 | E31: 320 | F31: =IF(AND(C31<>"",D31<>"",E31<>""),(C31+4*D31+E31)/6,0) | G31: Yes | H31: =IF(G31="Yes",ROUND(D31*$B$7,1),0) | I31: =F31+H31 | J31: Included | K31: Implementation
A32: QA-BE.9 | B32: Non-functional Testing (Docs) | C32: 200 | D32: 240 | E32: 260 | F32: =IF(AND(C32<>"",D32<>"",E32<>""),(C32+4*D32+E32)/6,0) | G32: No | H32: =IF(G32="Yes",ROUND(D32*$B$7,1),0) | I32: =F32+H32 | J32: Included | K32: Implementation
A33: QA-BE.10 | B33: Change-related (Smoke/Regression) | C33: 280 | D33: 320 | E33: 350 | F33: =IF(AND(C33<>"",D33<>"",E33<>""),(C33+4*D33+E33)/6,0) | G33: Yes | H33: =IF(G33="Yes",ROUND(D33*$B$7,1),0) | I33: =F33+H33 | J33: Included | K33: Implementation
A34: QA-BE.11 | B34: Test Closure | C34: 110 | D34: 120 | E34: 140 | F34: =IF(AND(C34<>"",D34<>"",E34<>""),(C34+4*D34+E34)/6,0) | G34: No | H34: =IF(G34="Yes",ROUND(D34*$B$7,1),0) | I34: =F34+H34 | J34: Included | K34: Implementation
A35: QA-MOB | B35: QA — Mobile stream
A36: QA-M.1 | B36: System Configuration | C36: 8 | D36: 14 | E36: 18 | F36: =IF(AND(C36<>"",D36<>"",E36<>""),(C36+4*D36+E36)/6,0) | G36: No | H36: =IF(G36="Yes",ROUND(D36*$B$7,1),0) | I36: =F36+H36 | J36: Not included | K36: Discovery
A37: QA-M.2 | B37: Test Environment Setup | C37: 6 | D37: 8 | E37: 10 | F37: =IF(AND(C37<>"",D37<>"",E37<>""),(C37+4*D37+E37)/6,0) | G37: No | H37: =IF(G37="Yes",ROUND(D37*$B$7,1),0) | I37: =F37+H37 | J37: Not included | K37: Discovery
A38: QA-M.3 | B38: Documentation Investigation | C38: 70 | D38: 90 | E38: 110 | F38: =IF(AND(C38<>"",D38<>"",E38<>""),(C38+4*D38+E38)/6,0) | G38: No | H38: =IF(G38="Yes",ROUND(D38*$B$7,1),0) | I38: =F38+H38 | J38: Included | K38: Implementation
A39: QA-M.4 | B39: Test Data | C39: 50 | D39: 60 | E39: 90 | F39: =IF(AND(C39<>"",D39<>"",E39<>""),(C39+4*D39+E39)/6,0) | G39: No | H39: =IF(G39="Yes",ROUND(D39*$B$7,1),0) | I39: =F39+H39 | J39: Included | K39: Implementation
A40: QA-M.5 | B40: Test Case design | C40: 180 | D40: 210 | E40: 230 | F40: =IF(AND(C40<>"",D40<>"",E40<>""),(C40+4*D40+E40)/6,0) | G40: No | H40: =IF(G40="Yes",ROUND(D40*$B$7,1),0) | I40: =F40+H40 | J40: Included | K40: Implementation
A41: QA-M.6 | B41: Functional Testing | C41: 150 | D41: 180 | E41: 220 | F41: =IF(AND(C41<>"",D41<>"",E41<>""),(C41+4*D41+E41)/6,0) | G41: Yes | H41: =IF(G41="Yes",ROUND(D41*$B$7,1),0) | I41: =F41+H41 | J41: Included | K41: Implementation
...

Sheet DevOps Estimation
A1: DevOps Estimation
A2: Purpose: | B2: Cloud-agnostic DevOps WBS: cost modelling, repo/IAM/CI tooling, environment build (Dev/Test/Stage/Prod), SSDLC pipelines, monitoring, backup/DR. Replaces the v1.4 single 'DevOps' role line with no hours.
A3: How to use: | B3: (1) Estimate Discovery cost-modelling activities first — they shape the cloud bill. (2) For environment rows, repeat the block per environment (Dev/Test/Stage/Prod). (3) Apply Contingency = Yes on cloud-vendor-dependent items (DNS, SSL, KMS, networking) where vendor surprises bite. (4) Toggle iOS/Android pipelines off if not applicable.
A4: Inputs: | B4: O/ML/P per row, Apply Contingency Y/N, Include, Phase, Deliverable.
A5: Outputs: | B5: DevOps roll-up flows to Buffers and Headcount and Cost.
A6: Linked tabs: | B6: Buffers & Non-Dev Activities (DevOps roll-up). Headcount and Cost (DevOps estimated hours). Fixed Costs (cloud bill — typically reflected as separate line items).
A7: Default contingency: | B7: 0.3 | C7: (used when Apply Contingency = Yes; multiplied by Most Likely)
A8: Cloud-agnostic DevOps catalogue. 30% default contingency reflects environment / vendor uncertainty.
A10: ID | B10: Service / Activity | C10: Optimistic | D10: Most Likely | E10: Pessimistic | F10: Expected | G10: Apply Contingency | H10: Contingency | I10: Final Expected | J10: Include | K10: Project Phase | L10: Deliverable | M10: Description / Scope | N10: Assumptions | O10: Notes
B11: TOTALS | C11: =SUM(C12:C54) | D11: =SUM(D12:D54) | E11: =SUM(E12:E54) | F11: =SUM(F12:F54) | H11: =SUM(H12:H54) | I11: =SUMIF(J12:J54,"Included",I12:I54) | J11: (only Included counted at right)
A12: DO-1 | B12: Discovery — cost / sizing
A13: DO-1.1 | B13: Estimation of infra cost (10k MAU baseline) | C13: 10 | D13: 10 | E13: 8 | F13: =IF(AND(C13<>"",D13<>"",E13<>""),(C13+4*D13+E13)/6,0) | G13: Yes | H13: =IF(G13="Yes",ROUND(D13*$B$7,1),0) | I13: =F13+H13 | J13: Included | K13: Discovery | L13: Infra cost model
A14: DO-1.2 | B14: Additional services costs | C14: 5 | D14: 5 | E14: 4 | F14: =IF(AND(C14<>"",D14<>"",E14<>""),(C14+4*D14+E14)/6,0) | G14: Yes | H14: =IF(G14="Yes",ROUND(D14*$B$7,1),0) | I14: =F14+H14 | J14: Included | K14: Discovery
A15: DO-1.3 | B15: Cost optimization options | C15: 8 | D15: 11 | E15: 11 | F15: =IF(AND(C15<>"",D15<>"",E15<>""),(C15+4*D15+E15)/6,0) | G15: Yes | H15: =IF(G15="Yes",ROUND(D15*$B$7,1),0) | I15: =F15+H15 | J15: Included | K15: Discovery
A16: DO-1.4 | B16: Customer presentation of cost model | C16: 3 | D16: 4 | E16: 4 | F16: =IF(AND(C16<>"",D16<>"",E16<>""),(C16+4*D16+E16)/6,0) | G16: Yes | H16: =IF(G16="Yes",ROUND(D16*$B$7,1),0) | I16: =F16+H16 | J16: Included | K16: Discovery
A17: DO-2 | B17: Implementation — preparing tooling
A18: DO-2.1 | B18: Pre-flight artefact check | C18: 2 | D18: 3 | E18: 2 | F18: =IF(AND(C18<>"",D18<>"",E18<>""),(C18+4*D18+E18)/6,0) | G18: No | H18: =IF(G18="Yes",ROUND(D18*$B$7,1),0) | I18: =F18+H18 | J18: Included | K18: Implementation
A19: DO-2.2 | B19: Setup repositories (VCS) | C19: 2 | D19: 3 | E19: 2 | F19: =IF(AND(C19<>"",D19<>"",E19<>""),(C19+4*D19+E19)/6,0) | G19: No | H19: =IF(G19="Yes",ROUND(D19*$B$7,1),0) | I19: =F19+H19 | J19: Included | K19: Implementation
A20: DO-2.3 | B20: Setup domain names & DNS | C20: 2 | D20: 3 | E20: 2 | F20: =IF(AND(C20<>"",D20<>"",E20<>""),(C20+4*D20+E20)/6,0) | G20: Yes | H20: =IF(G20="Yes",ROUND(D20*$B$7,1),0) | I20: =F20+H20 | J20: Included | K20: Implementation
A21: DO-2.4 | B21: IAM roles for team members | C21: 4 | D21: 6 | E21: 4 | F21: =IF(AND(C21<>"",D21<>"",E21<>""),(C21+4*D21+E21)/6,0) | G21: No | H21: =IF(G21="Yes",ROUND(D21*$B$7,1),0) | I21: =F21+H21 | J21: Included | K21: Implementation
A22: DO-2.5 | B22: Package registry | C22: 2 | D22: 2 | E22: 2 | F22: =IF(AND(C22<>"",D22<>"",E22<>""),(C22+4*D22+E22)/6,0) | G22: No | H22: =IF(G22="Yes",ROUND(D22*$B$7,1),0) | I22: =F22+H22 | J22: Included | K22: Implementation
A23: DO-2.6 | B23: CI/CD management system | C23: 8 | D23: 11 | E23: 8 | F23: =IF(AND(C23<>"",D23<>"",E23<>""),(C23+4*D23+E23)/6,0) | G23: No | H23: =IF(G23="Yes",ROUND(D23*$B$7,1),0) | I23: =F23+H23 | J23: Included | K23: Implementation
A24: DO-2.7 | B24: Quality gate analyzer | C24: 3 | D24: 4 | E24: 3 | F24: =IF(AND(C24<>"",D24<>"",E24<>""),(C24+4*D24+E24)/6,0) | G24: Yes | H24: =IF(G24="Yes",ROUND(D24*$B$7,1),0) | I24: =F24+H24 | J24: Included | K24: Implementation
A25: DO-2.8 | B25: OWASP / dependency scanning | C25: 8 | D25: 11 | E25: 8 | F25: =IF(AND(C25<>"",D25<>"",E25<>""),(C25+4*D25+E25)/6,0) | G25: Yes | H25: =IF(G25="Yes",ROUND(D25*$B$7,1),0) | I25: =F25+H25 | J25: Included | K25: Implementation
A26: DO-2.9 | B26: IaC tools setup (Terraform/Pulumi) | C26: 8 | D26: 11 | E26: 8 | F26: =IF(AND(C26<>"",D26<>"",E26<>""),(C26+4*D26+E26)/6,0) | G26: No | H26: =IF(G26="Yes",ROUND(D26*$B$7,1),0) | I26: =F26+H26 | J26: Included | K26: Implementation
A27: DO-2.10 | B27: PaaS framework adaptation | C27: 24 | D27: 24 | E27: 24 | F27: =IF(AND(C27<>"",D27<>"",E27<>""),(C27+4*D27+E27)/6,0) | G27: Yes | H27: =IF(G27="Yes",ROUND(D27*$B$7,1),0) | I27: =F27+H27 | J27: Included | K27: Implementation
A28: DO-3 | B28: Environments — Development
A29: DO-3.1 | B29: Dev account setup | C29: 2 | D29: 3 | E29: 3 | F29: =IF(AND(C29<>"",D29<>"",E29<>""),(C29+4*D29+E29)/6,0) | G29: Yes | H29: =IF(G29="Yes",ROUND(D29*$B$7,1),0) | I29: =F29+H29 | J29: Included | K29: Implementation
A30: DO-3.2 | B30: FE deployment in Dev | C30: 3 | D30: 4 | E30: 4 | F30: =IF(AND(C30<>"",D30<>"",E30<>""),(C30+4*D30+E30)/6,0) | G30: No | H30: =IF(G30="Yes",ROUND(D30*$B$7,1),0) | I30: =F30+H30 | J30: Included | K30: Implementation
A31: DO-3.3 | B31: BE infrastructure (containers/K8s) | C31: 16 | D31: 16 | E31: 24 | F31: =IF(AND(C31<>"",D31<>"",E31<>""),(C31+4*D31+E31)/6,0) | G31: No | H31: =IF(G31="Yes",ROUND(D31*$B$7,1),0) | I31: =F31+H31 | J31: Included | K31: Implementation
A32: DO-3.4 | B32: VPC / subnets / security groups | C32: 2 | D32: 3 | E32: 3 | F32: =IF(AND(C32<>"",D32<>"",E32<>""),(C32+4*D32+E32)/6,0) | G32: No | H32: =IF(G32="Yes",ROUND(D32*$B$7,1),0) | I32: =F32+H32 | J32: Included | K32: Implementation
A33: DO-3.5 | B33: VPN access | C33: 8 | D33: 8 | E33: 10 | F33: =IF(AND(C33<>"",D33<>"",E33<>""),(C33+4*D33+E33)/6,0) | G33: No | H33: =IF(G33="Yes",ROUND(D33*$B$7,1),0) | I33: =F33+H33 | J33: Included | K33: Implementation
A34: DO-3.6 | B34: ALB / target groups / WAF | C34: 6 | D34: 6 | E34: 9 | F34: =IF(AND(C34<>"",D34<>"",E34<>""),(C34+4*D34+E34)/6,0) | G34: No | H34: =IF(G34="Yes",ROUND(D34*$B$7,1),0) | I34: =F34+H34 | J34: Included | K34: Implementation
A35: DO-3.7 | B35: Object storage | C35: 1 | D35: 2 | E35: 2 | F35: =IF(AND(C35<>"",D35<>"",E35<>""),(C35+4*D35+E35)/6,0) | G35: Yes | H35: =IF(G35="Yes",ROUND(D35*$B$7,1),0) | I35: =F35+H35 | J35: Included | K35: Implementation
A36: DO-3.8 | B36: Relational DB | C36: 6 | D36: 6 | E36: 8 | F36: =IF(AND(C36<>"",D36<>"",E36<>""),(C36+4*D36+E36)/6,0) | G36: Yes | H36: =IF(G36="Yes",ROUND(D36*$B$7,1),0) | I36: =F36+H36 | J36: Included | K36: Implementation
A37: DO-3.9 | B37: Non-relational DB | C37: 4 | D37: 4 | E37: 6 | F37: =IF(AND(C37<>"",D37<>"",E37<>""),(C37+4*D37+E37)/6,0) | G37: Yes | H37: =IF(G37="Yes",ROUND(D37*$B$7,1),0) | I37: =F37+H37 | J37: Included | K37: Implementation
A38: DO-3.10 | B38: Cache (ElastiCache/Redis) | C38: 5 | D38: 5 | E38: 7 | F38: =IF(AND(C38<>"",D38<>"",E38<>""),(C38+4*D38+E38)/6,0) | G38: Yes | H38: =IF(G38="Yes",ROUND(D38*$B$7,1),0) | I38: =F38+H38 | J38: Included | K38: Implementation
A39: DO-3.11 | B39: CDN / distribution / cert | C39: 3 | D39: 5 | E39: 5 | F39: =IF(AND(C39<>"",D39<>"",E39<>""),(C39+4*D39+E39)/6,0) | G39: Yes | H39: =IF(G39="Yes",ROUND(D39*$B$7,1),0) | I39: =F39+H39 | J39: Included | K39: Implementation
A40: DO-4 | B40: Environments — Test / Stage / Prod
A41: DO-4.1 | B41: Test environment build | C41: 16 | D41: 24 | E41: 32 | F41: =IF(AND(C41<>"",D41<>"",E41<>""),(C41+4*D41+E41)/6,0) | G41: Yes | H41: =IF(G41="Yes",ROUND(D41*$B$7,1),0) | I41: =F41+H41 | J41: Included | K41: Implementation
...

Sheet PM Estimation
A1: Project Management Estimation
A2: Purpose: | B2: PM activity catalogue — Discovery prestart, governance (RACI / DoR / DoD / Communication & Escalation matrices), project charter, sprint cadence, reporting, change management, closure. Replaces v1.4's flat 0.25 FTE PM allocation.
